<?xml version="1.0" ?>
<!-- =================================================================================== -->
<!-- |    This document was autogenerated by xacro from ur5_joint_limited_robot.urdf.xacro | -->
<!-- |    EDITING THIS FILE BY HAND IS NOT RECOMMENDED                                 | -->
<!-- =================================================================================== -->
<robot name="ur5" xmlns:xacro="http://www.ros.org/wiki/xacro">

<link name="world"/>
  <joint name="world_joint" type="fixed">
    <parent link="world"/>
    <child link="body_link"/>
    <origin rpy="0.0 0.0 0.0" xyz="0.0 0.0 0.0"/>
  </joint>
<link name="body_link">
    <visual>
        <origin rpy="0.0 0.0 1.570796325" xyz="0.0 0.0 0.0"/>
 <geometry>
   <mesh filename="package://ur5/meshes/visual/Body.obj"/>
 </geometry>
 <material name="LightGrey">
   <color rgba="0.7 0.7 0.7 1.0"/>
 </material>
</visual>
</link>

<joint name="neck_yaw_joint" type="revolute">
<parent link="body_link"/>
<child link="neck_yaw_link"/>
<origin rpy="0.0 0.0 1.570796325 " xyz="0.34 -0.03 0.915"/>
<axis xyz="0 0 1"/>
<limit effort="150.0" lower="-3.14159265" upper="3.14159265" velocity="3.15"/>
<dynamics damping="0.0" friction="0.0"/>
</joint>

<link name="neck_yaw_link">
<visual>
 <geometry>
   <mesh filename="package://ur5/meshes/visual/NeckYaw.obj"/>
 </geometry>
</visual>
<collision>
 <geometry>
   <mesh filename="package://ur5/meshes/collision/NeckYaw.stl"/>
 </geometry>
    <origin rpy="1.570796325 0.0 0.0" xyz="0.0 0.0 0.0"/>
</collision>
<inertial>
 <mass value="0.1"/>
 <origin rpy="0 0 0" xyz="0.0 0.0 0.0"/>
 <inertia ixx="0.001" ixy="0.0" ixz="0.0" iyy="0.001" iyz="0.0" izz="0.001"/>
</inertial>
</link>

<joint name="neck_pitch_joint" type="revolute">
<parent link="neck_yaw_link"/>
<child link="neck_pitch_link"/>
    <!--<origin rpy="-0.05235987755982989 0 0" xyz="-0.03 0.0 0.05"/> -->
    <origin rpy="0 0 0" xyz="-0.03 0.0 0.05"/>
<axis xyz="-1 0 0"/>
<limit effort="150.0" lower="-3.14159265" upper="3.14159265" velocity="3.15"/>
<dynamics damping="0.0" friction="0.0"/>
</joint>

<link name="neck_pitch_link">
<visual>
 <geometry>
   <mesh filename="package://ur5/meshes/visual/NeckPitch.obj"/>
 </geometry>
</visual>
<collision>
 <geometry>
   <mesh filename="package://ur5/meshes/collision/NeckPitch.stl"/>
 </geometry>
    <origin rpy="1.570796325 0.0 0.0" xyz="0.0 0.0 0.0"/>
</collision>
<inertial>
 <mass value="0.1"/>
 <origin rpy="0 0 0" xyz="0.0 0.0 0.0"/>
 <inertia ixx="0.001" ixy="0.0" ixz="0.0" iyy="0.001" iyz="0.0" izz="0.001"/>
</inertial>
</link>

<joint name="left_cam_joint" type="fixed">
<parent link="neck_pitch_link"/>
<child link="left_cam_link"/>
    <origin rpy="0 0 0" xyz="0.08846 -0.03125 0.05832"/>
</joint>
<link name="left_cam_link">
</link>

<joint name="left_view_joint" type="fixed">
<parent link="left_cam_link"/>
<child link="left_view_link"/>
    <origin rpy="0 0 0" xyz="0. -0.1 0."/>
</joint>

<link name="left_view_link">
</link>

<joint name="right_cam_joint" type="fixed">
<parent link="neck_pitch_link"/>
<child link="right_cam_link"/>
    <origin rpy="0 0 0" xyz="0.02546 -0.03125 0.05832"/>
</joint>
<link name="right_cam_link">
</link>

<joint name="right_view_joint" type="fixed">
<parent link="right_cam_link"/>
<child link="right_view_link"/>
    <origin rpy="0 0 0" xyz="0. -0.1 0."/>
</joint>

<link name="right_view_link">
</link>

<joint name="l_body_joint" type="fixed">
    <parent link="body_link"/>
    <child link="l_base_link"/>
    <origin rpy="-1.570796325 0.785398163397 0.0" xyz="0.0 0.2 0.93"/>
</joint>

<link name="l_base_link">
<visual>
 <geometry>
   <mesh filename="package://ur5/meshes/visual/Base.obj"/>
 </geometry>
 <material name="LightGrey">
   <color rgba="0.7 0.7 0.7 1.0"/>
 </material>
</visual>
<collision>
 <geometry>
   <mesh filename="package://ur5/meshes/collision/Base.stl"/>
 </geometry>
    <origin rpy="1.570796325 0.0 0.0" xyz="0.0 0.0 0.0"/>
</collision>
<inertial>
 <mass value="4.0"/>
 <origin rpy="0 0 0" xyz="0.0 0.0 0.0"/>
 <inertia ixx="0.00443333156" ixy="0.0" ixz="0.0" iyy="0.00443333156" iyz="0.0" izz="0.0072"/>
</inertial>
</link>


<joint name="l_shoulder_pan_joint" type="revolute">
<parent link="l_base_link"/>
<child link="l_shoulder_link"/>
<origin rpy="0.0 0.0 0.0" xyz="0.0 0.0 0.089159"/>
<axis xyz="0 0 1"/>
<limit effort="150.0" lower="-3.14159265" upper="3.14159265" velocity="3.15"/>
<dynamics damping="0.0" friction="0.0"/>
</joint>
<link name="l_shoulder_link">
<visual>
 <geometry>
   <mesh filename="package://ur5/meshes/visual/Shoulder.obj"/>
 </geometry>
 <material name="LightGrey">
   <color rgba="0.7 0.7 0.7 1.0"/>
 </material>
</visual>
<collision>
 <geometry>
   <mesh filename="package://ur5/meshes/collision/Shoulder.stl"/>
 </geometry>
    <origin rpy="1.570796325 0.0 0.0" xyz="0.0 0.0 0.0"/>
</collision>
<inertial>
 <mass value="3.7"/>
 <origin rpy="0 0 0" xyz="0.0 0.0 0.0"/>
 <inertia ixx="0.010267495893" ixy="0.0" ixz="0.0" iyy="0.010267495893" iyz="0.0" izz="0.00666"/>
</inertial>
</link>
<joint name="l_shoulder_lift_joint" type="revolute">
<parent link="l_shoulder_link"/>
<child link="l_upper_arm_link"/>
<origin rpy="0.0 1.570796325 0.0" xyz="0.0 0.13585 0.0"/>
<axis xyz="0 1 0"/>
<limit effort="150.0" lower="-3.14159265" upper="3.14159265" velocity="3.15"/>
<dynamics damping="0.0" friction="0.0"/>
</joint>
<link name="l_upper_arm_link">
<visual>
 <geometry>
   <mesh filename="package://ur5/meshes/visual/UpperArm.obj"/>
 </geometry>
 <material name="LightGrey">
   <color rgba="0.7 0.7 0.7 1.0"/>
 </material>
</visual>
<collision>
 <geometry>
   <mesh filename="package://ur5/meshes/collision/UpperArm.stl"/>
 </geometry>
    <origin rpy="1.570796325 0.0 0.0" xyz="0.0 0.0 0.0"/>
</collision>
<inertial>
 <mass value="8.393"/>
 <origin rpy="0 0 0" xyz="0.0 0.0 0.28"/>
 <inertia ixx="0.22689067591" ixy="0.0" ixz="0.0" iyy="0.22689067591" iyz="0.0" izz="0.0151074"/>
</inertial>
</link>

<joint name="l_elbow_joint" type="revolute">
<parent link="l_upper_arm_link"/>
<child link="l_forearm_link"/>
<origin rpy="0.0 0.0 0.0" xyz="0.0 -0.1197 0.425"/>
<axis xyz="0 1 0"/>
<limit effort="150.0" lower="-3.14159265" upper="3.14159265" velocity="3.15"/>
<dynamics damping="0.0" friction="0.0"/>
</joint>

<link name="l_forearm_link">
<visual>
 <geometry>
   <mesh filename="package://ur5/meshes/visual/ForeArm.obj"/>
 </geometry>
 <material name="LightGrey">
   <color rgba="0.7 0.7 0.7 1.0"/>
 </material>
</visual>
<collision>
 <geometry>
   <mesh filename="package://ur5/meshes/collision/ForeArm.stl"/>
 </geometry>
    <origin rpy="1.570796325 0.0 0.0" xyz="0.0 0.0 0.0"/>
</collision>
<inertial>
 <mass value="2.275"/>
 <origin rpy="0 0 0" xyz="0.0 0.0 0.25"/>
 <inertia ixx="0.049443313556" ixy="0.0" ixz="0.0" iyy="0.049443313556" iyz="0.0" izz="0.004095"/>
</inertial>
</link>

<joint name="l_wrist_1_joint" type="revolute">
<parent link="l_forearm_link"/>
<child link="l_wrist_1_link"/>
<origin rpy="0.0 1.570796325 0.0" xyz="0.0 0.0 0.39225"/>
<axis xyz="0 1 0"/>
<limit effort="28.0" lower="-3.14159265" upper="3.14159265" velocity="3.2"/>
<dynamics damping="0.0" friction="0.0"/>
</joint>

<link name="l_wrist_1_link">
<visual>
 <geometry>
   <mesh filename="package://ur5/meshes/visual/Wrist1.obj"/>
 </geometry>
 <material name="LightGrey">
   <color rgba="0.7 0.7 0.7 1.0"/>
 </material>
</visual>
<collision>
 <geometry>
   <mesh filename="package://ur5/meshes/collision/Wrist1.stl"/>
 </geometry>
    <origin rpy="1.570796325 0.0 0.0" xyz="0.0 0.0 0.0"/>
</collision>
<inertial>
 <mass value="1.219"/>
 <origin rpy="0 0 0" xyz="0.0 0.0 0.0"/>
 <inertia ixx="0.111172755531" ixy="0.0" ixz="0.0" iyy="0.111172755531" iyz="0.0" izz="0.21942"/>
</inertial>
</link>

<joint name="l_wrist_2_joint" type="revolute">
<parent link="l_wrist_1_link"/>
<child link="l_wrist_2_link"/>
<origin rpy="0.0 0.0 0.0" xyz="0.0 0.093 0.0"/>
<axis xyz="0 0 1"/>
<limit effort="28.0" lower="-3.14159265" upper="3.14159265" velocity="3.2"/>
<dynamics damping="0.0" friction="0.0"/>
</joint>

<link name="l_wrist_2_link">
<visual>
 <geometry>
   <mesh filename="package://ur5/meshes/visual/Wrist2.obj"/>
 </geometry>
 <material name="LightGrey">
   <color rgba="0.7 0.7 0.7 1.0"/>
 </material>
</visual>
<collision>
 <geometry>
   <mesh filename="package://ur5/meshes/collision/Wrist2.stl"/>
 </geometry>
    <origin rpy="1.570796325 0.0 0.0" xyz="0.0 0.0 0.0"/>
</collision>
<inertial>
 <mass value="1.219"/>
 <origin rpy="0 0 0" xyz="0.0 0.0 0.0"/>
 <inertia ixx="0.111172755531" ixy="0.0" ixz="0.0" iyy="0.111172755531" iyz="0.0" izz="0.21942"/>
</inertial>
</link>

<joint name="l_wrist_3_joint" type="revolute">
<parent link="l_wrist_2_link"/>
<child link="l_wrist_3_link"/>
<origin rpy="0.0 0.0 0.0" xyz="0.0 0.0 0.09465"/>
<axis xyz="0 1 0"/>
<limit effort="28.0" lower="-3.14159265" upper="3.14159265" velocity="3.2"/>
<dynamics damping="0.0" friction="0.0"/>
</joint>

<link name="l_wrist_3_link">
<visual>
 <geometry>
   <mesh filename="package://ur5/meshes/visual/Wrist3.obj"/>
 </geometry>
 <material name="LightGrey">
   <color rgba="0.7 0.7 0.7 1.0"/>
 </material>
</visual>
<collision>
 <geometry>
   <mesh filename="package://ur5/meshes/collision/Wrist3.stl"/>
 </geometry>
    <origin rpy="1.570796325 0.0 0.0" xyz="0.0 0.0 0.0"/>
</collision>
<inertial>
 <mass value="0.1879"/>
 <origin rpy="0 0 0" xyz="0.0 0.0 0.0"/>
 <inertia ixx="0.0171364731454" ixy="0.0" ixz="0.0" iyy="0.0171364731454" iyz="0.0" izz="0.033822"/>
</inertial>
</link>

<joint name="l_fixed_joint" type="fixed">
<parent link="l_wrist_3_link"/>
<child link="l_fixed_link"/>
<origin rpy="0.0 0.0 1.570796325" xyz="0.0 0.0823 0.0"/>
</joint>

<link name="l_fixed_link">
<visual>
 <geometry>
   <mesh filename="package://ur5/meshes/visual/FixedL.obj"/>
 </geometry>
 <material name="LightGrey">
   <color rgba="0.7 0.7 0.7 1.0"/>
 </material>
</visual>
<collision>
    <origin rpy="1.570796325 0.0 0.0" xyz="0.0 0.0 0.0"/>
 <geometry>
   <mesh filename="package://ur5/meshes/collision/FixedL.stl"/>
 </geometry>
</collision>
    <!-- inaccurate -->
<inertial>
 <mass value="0.1"/>
 <origin rpy="0 0 0" xyz="0.0 0.0 0.0"/>
 <inertia ixx="0.01" ixy="0.0" ixz="0.0" iyy="0.01" iyz="0.0" izz="0.01"/>
</inertial>
</link>

<joint name="l_move_joint" type="revolute">
<parent link="l_fixed_link"/>
<child link="l_move_link"/>
<origin rpy="0.0 0.0 0" xyz="0.053 0.0085 0.0"/>
<axis xyz="0 0 1"/>
<limit effort="28.0" lower="-3.14159265" upper="3.14159265" velocity="3.2"/>
</joint>

<joint name="l_fixed_connector_joint" type="fixed">
<parent link="l_fixed_link"/>
<child link="l_fixed_connector_link"/>
    <!--<origin rpy="0.0 0.0 0" xyz="0.178 -0.0405 0.0"/>-->
    -<origin rpy="0.0 0.0 0" xyz="0.173 -0.04150 0.0"/>
<axis xyz="0 0 1"/>
</joint>

<link name="l_fixed_connector_link">
<visual>
 <geometry>
   <mesh filename="package://ur5/meshes/visual/FixedConnectorL.obj"/>
 </geometry>
 <material name="LightGrey">
   <color rgba="0.7 0.7 0.7 1.0"/>
 </material>
</visual>
<collision>
    <origin rpy="1.570796325 0.0 0.0" xyz="0.0 0.0 0.0"/>
 <geometry>
   <mesh filename="package://ur5/meshes/collision/FixedConnectorL.stl"/>
 </geometry>
</collision>
    <!-- inaccurate -->
<inertial>
 <mass value="0.01"/>
 <origin rpy="0 0 0" xyz="0.0 0.0 0.0"/>
 <inertia ixx="0.001" ixy="0.0" ixz="0.0" iyy="0.001" iyz="0.0" izz="0.001"/>
</inertial>
</link>

<joint name="l_fixed_sensor_joint" type="fixed">
<parent link="l_fixed_connector_link"/>
<child link="l_fixed_sensor_link"/>
<origin rpy="0.0 0.0 0" xyz="0.005 0.0010 0.0"/>
<axis xyz="0 0 1"/>
</joint>

<link name="l_fixed_sensor_link">
<visual>
 <geometry>
   <mesh filename="package://ur5/meshes/visual/FixedSensorL.obj"/>
 </geometry>
 <material name="LightGrey">
   <color rgba="0.7 0.7 0.7 1.0"/>
 </material>
</visual>
<collision>
    <origin rpy="1.570796325 0.0 0.0" xyz="0.0 0.0 0.0"/>
 <geometry>
   <mesh filename="package://ur5/meshes/collision/FixedSensorL.stl"/>
 </geometry>
</collision>
<!-- inaccurate -->
<inertial>
 <mass value="0.01"/>
 <origin rpy="0 0 0" xyz="0.0 0.0 0.0"/>
 <inertia ixx="0.001" ixy="0.0" ixz="0.0" iyy="0.001" iyz="0.0" izz="0.001"/>
</inertial>
</link>

<joint name="l_fixed_finger_joint" type="fixed">
<parent link="l_fixed_sensor_link"/>
<child link="l_fixed_finger_link"/>
<origin rpy="0.0 0.0 0" xyz="0.023 0.0 0.0"/>
<axis xyz="0 0 1"/>
<limit effort="28.0" lower="-3.14159265" upper="3.14159265" velocity="3.2"/>
</joint>

<link name="l_fixed_finger_link">
<visual>
 <geometry>
   <mesh filename="package://ur5/meshes/visual/FixedFingerL.obj"/>
 </geometry>
 <material name="LightGrey">
   <color rgba="0.7 0.7 0.7 1.0"/>
 </material>
</visual>
<collision>
    <origin rpy="1.570796325 0.0 0.0" xyz="0.0 0.0 0.0"/>
 <geometry>
   <mesh filename="package://ur5/meshes/collision/FixedFingerL.stl"/>
 </geometry>
</collision>
    <!--inaccurate-->
<inertial>
 <mass value="0.01"/>
 <origin rpy="0 0 0" xyz="0.0 0.0 0.0"/>
 <inertia ixx="0.001" ixy="0.0" ixz="0.0" iyy="0.001" iyz="0.0" izz="0.001"/>
</inertial>
</link>

<link name="l_move_link">
<visual>
 <geometry>
   <mesh filename="package://ur5/meshes/visual/MoveL.obj"/>
 </geometry>
 <material name="LightGrey">
   <color rgba="0.7 0.7 0.7 1.0"/>
 </material>
</visual>
<collision>
    <origin rpy="1.570796325 0.0 0.0" xyz="0.0 0.0 0.0"/>
 <geometry>
   <mesh filename="package://ur5/meshes/collision/MoveL.stl"/>
 </geometry>
</collision>
    <!--inaccurate-->
<inertial>
 <mass value="0.01"/>
 <origin rpy="0 0 0" xyz="0.0 0.0 0.0"/>
 <inertia ixx="0.001" ixy="0.0" ixz="0.0" iyy="0.001" iyz="0.0" izz="0.001"/>
</inertial>
</link>

<joint name="l_move_connector_joint" type="fixed">
<parent link="l_move_link"/>
<child link="l_move_connector_link"/>
    -<origin rpy="0.0 0.0 0" xyz="0.1205 -0.01975 0.0"/>
<axis xyz="0 0 1"/>
</joint>

<link name="l_move_connector_link">
<visual>
 <geometry>
   <mesh filename="package://ur5/meshes/visual/MoveConnectorL.obj"/>
 </geometry>
 <material name="LightGrey">
   <color rgba="0.7 0.7 0.7 1.0"/>
 </material>
</visual>
<collision>
    <origin rpy="1.570796325 0.0 0.0" xyz="0.0 0.0 0.0"/>
 <geometry>
   <mesh filename="package://ur5/meshes/collision/MoveConnectorL.stl"/>
 </geometry>
</collision>
    <!--inaccurate-->
<inertial>
 <mass value="0.01"/>
 <origin rpy="0 0 0" xyz="0.0 0.0 0.0"/>
 <inertia ixx="0.001" ixy="0.0" ixz="0.0" iyy="0.001" iyz="0.0" izz="0.001"/>
</inertial>
</link>

<joint name="l_move_sensor_joint" type="fixed">
<parent link="l_move_connector_link"/>
<child link="l_move_sensor_link"/>
    <origin rpy="0.0 0.0 0" xyz="0.0045 0.00375 0.0"/>
<axis xyz="0 0 1"/>
</joint>

<link name="l_move_sensor_link">
<visual>
 <geometry>
   <mesh filename="package://ur5/meshes/visual/MoveSensorL.obj"/>
 </geometry>
 <material name="LightGrey">
   <color rgba="0.7 0.7 0.7 1.0"/>
 </material>
</visual>
<collision>
    <origin rpy="1.570796325 0.0 0.0" xyz="0.0 0.0 0.0"/>
 <geometry>
   <mesh filename="package://ur5/meshes/collision/MoveSensorL.stl"/>
 </geometry>
</collision>
    <!--inaccurate-->
<inertial>
 <mass value="0.01"/>
 <origin rpy="0 0 0" xyz="0.0 0.0 0.0"/>
 <inertia ixx="0.001" ixy="0.0" ixz="0.0" iyy="0.001" iyz="0.0" izz="0.001"/>
</inertial>
</link>

<joint name="l_move_finger_joint" type="fixed">
<parent link="l_move_sensor_link"/>
<child link="l_move_finger_link"/>
<origin rpy="0.0 0.0 0" xyz="0.023 0.0 0.0"/>
<axis xyz="0 0 1"/>
</joint>

<link name="l_move_finger_link">
<visual>
 <geometry>
   <mesh filename="package://ur5/meshes/visual/MoveFingerL.obj"/>
 </geometry>
 <material name="LightGrey">
   <color rgba="0.7 0.7 0.7 1.0"/>
 </material>
</visual>
<collision>
    <origin rpy="1.570796325 0.0 0.0" xyz="0.0 0.0 0.0"/>
 <geometry>
   <mesh filename="package://ur5/meshes/collision/MoveFingerL.stl"/>
 </geometry>
</collision>
    <!--inaccurate-->
<inertial>
 <mass value="0.01"/>
 <origin rpy="0 0 0" xyz="0.0 0.0 0.0"/>
 <inertia ixx="0.001" ixy="0.0" ixz="0.0" iyy="0.001" iyz="0.0" izz="0.001"/>
</inertial>
</link>

<joint name="body_joint" type="fixed">
<parent link="body_link"/>
<child link="r_base_link"/>
<origin rpy="1.570796325 -2.356194490192 0.0" xyz="0.0 -0.2 0.93"/>
</joint>
<link name="r_base_link">
<visual>
 <geometry>
   <mesh filename="package://ur5/meshes/visualBase.obj"/>
 </geometry>
 <material name="LightGrey">
   <color rgba="0.7 0.7 0.7 1.0"/>
 </material>
</visual>
<collision>
 <geometry>
   <mesh filename="package://ur5/meshes/collision/Base.stl"/>
 </geometry>
    <origin rpy="1.570796325 0.0 0.0" xyz="0.0 0.0 0.0"/>
</collision>
<inertial>
 <mass value="4.0"/>
 <origin rpy="0 0 0" xyz="0.0 0.0 0.0"/>
 <inertia ixx="0.00443333156" ixy="0.0" ixz="0.0" iyy="0.00443333156" iyz="0.0" izz="0.0072"/>
</inertial>
</link>
<joint name="r_shoulder_pan_joint" type="revolute">
<parent link="r_base_link"/>
<child link="r_shoulder_link"/>
<origin rpy="0.0 0.0 0.0" xyz="0.0 0.0 0.089159"/>
<axis xyz="0 0 1"/>
<limit effort="150.0" lower="-3.14159265" upper="3.14159265" velocity="3.15"/>
<dynamics damping="0.0" friction="0.0"/>
</joint>
<link name="r_shoulder_link">
<visual>
 <geometry>
   <mesh filename="package://ur5/meshes/visual/Shoulder.obj"/>
 </geometry>
 <material name="LightGrey">
   <color rgba="0.7 0.7 0.7 1.0"/>
 </material>
</visual>
<collision>
 <geometry>
   <mesh filename="package://ur5/meshes/collision/Shoulder.stl"/>
 </geometry>
    <origin rpy="1.570796325 0.0 0.0" xyz="0.0 0.0 0.0"/>
</collision>
<inertial>
 <mass value="3.7"/>
 <origin rpy="0 0 0" xyz="0.0 0.0 0.0"/>
 <inertia ixx="0.010267495893" ixy="0.0" ixz="0.0" iyy="0.010267495893" iyz="0.0" izz="0.00666"/>
</inertial>
</link>
<joint name="r_shoulder_lift_joint" type="revolute">
<parent link="r_shoulder_link"/>
<child link="r_upper_arm_link"/>
<origin rpy="0.0 1.570796325 0.0" xyz="0.0 0.13585 0.0"/>
<axis xyz="0 1 0"/>
<limit effort="150.0" lower="-3.14159265" upper="3.14159265" velocity="3.15"/>
<dynamics damping="0.0" friction="0.0"/>
</joint>
<link name="r_upper_arm_link">
<visual>
 <geometry>
   <mesh filename="package://ur5/meshes/visual/UpperArm.obj"/>
 </geometry>
 <material name="LightGrey">
   <color rgba="0.7 0.7 0.7 1.0"/>
 </material>
</visual>
<collision>
 <geometry>
   <mesh filename="package://ur5/meshes/collision/UpperArm.stl"/>
 </geometry>
    <origin rpy="1.570796325 0.0 0.0" xyz="0.0 0.0 0.0"/>
</collision>
<inertial>
 <mass value="8.393"/>
 <origin rpy="0 0 0" xyz="0.0 0.0 0.28"/>
 <inertia ixx="0.22689067591" ixy="0.0" ixz="0.0" iyy="0.22689067591" iyz="0.0" izz="0.0151074"/>
</inertial>
</link>
<joint name="r_elbow_joint" type="revolute">
<parent link="r_upper_arm_link"/>
<child link="r_forearm_link"/>
<origin rpy="0.0 0.0 0.0" xyz="0.0 -0.1197 0.425"/>
<axis xyz="0 1 0"/>
<limit effort="150.0" lower="-3.14159265" upper="3.14159265" velocity="3.15"/>
<dynamics damping="0.0" friction="0.0"/>
</joint>
<link name="r_forearm_link">
<visual>
 <geometry>
   <mesh filename="package://ur5/meshes/visual/ForeArm.obj"/>
 </geometry>
 <material name="LightGrey">
   <color rgba="0.7 0.7 0.7 1.0"/>
 </material>
</visual>
<collision>
 <geometry>
   <mesh filename="package://ur5/meshes/collision/ForeArm.stl"/>
 </geometry>
    <origin rpy="1.570796325 0.0 0.0" xyz="0.0 0.0 0.0"/>
</collision>
<inertial>
 <mass value="2.275"/>
 <origin rpy="0 0 0" xyz="0.0 0.0 0.25"/>
 <inertia ixx="0.049443313556" ixy="0.0" ixz="0.0" iyy="0.049443313556" iyz="0.0" izz="0.004095"/>
</inertial>
</link>
<joint name="r_wrist_1_joint" type="revolute">
<parent link="r_forearm_link"/>
<child link="r_wrist_1_link"/>
<origin rpy="0.0 1.570796325 0.0" xyz="0.0 0.0 0.39225"/>
<axis xyz="0 1 0"/>
<limit effort="28.0" lower="-3.14159265" upper="3.14159265" velocity="3.2"/>
<dynamics damping="0.0" friction="0.0"/>
</joint>
<link name="r_wrist_1_link">
<visual>
 <geometry>
   <mesh filename="package://ur5/meshes/visual/Wrist1.obj"/>
 </geometry>
 <material name="LightGrey">
   <color rgba="0.7 0.7 0.7 1.0"/>
 </material>
</visual>
<collision>
 <geometry>
   <mesh filename="package://ur5/meshes/collision/Wrist1.stl"/>
 </geometry>
    <origin rpy="1.570796325 0.0 0.0" xyz="0.0 0.0 0.0"/>
</collision>
<inertial>
 <mass value="1.219"/>
 <origin rpy="0 0 0" xyz="0.0 0.0 0.0"/>
 <inertia ixx="0.111172755531" ixy="0.0" ixz="0.0" iyy="0.111172755531" iyz="0.0" izz="0.21942"/>
</inertial>
</link>
<joint name="r_wrist_2_joint" type="revolute">
<parent link="r_wrist_1_link"/>
<child link="r_wrist_2_link"/>
<origin rpy="0.0 0.0 0.0" xyz="0.0 0.093 0.0"/>
<axis xyz="0 0 1"/>
<limit effort="28.0" lower="-3.14159265" upper="3.14159265" velocity="3.2"/>
<dynamics damping="0.0" friction="0.0"/>
</joint>
<link name="r_wrist_2_link">
<visual>
 <geometry>
   <mesh filename="package://ur5/meshes/visual/Wrist2.obj"/>
 </geometry>
 <material name="LightGrey">
   <color rgba="0.7 0.7 0.7 1.0"/>
 </material>
</visual>
<collision>
 <geometry>
   <mesh filename="package://ur5/meshes/collision/Wrist2.stl"/>
 </geometry>
    <origin rpy="1.570796325 0.0 0.0" xyz="0.0 0.0 0.0"/>
</collision>
<inertial>
 <mass value="1.219"/>
 <origin rpy="0 0 0" xyz="0.0 0.0 0.0"/>
 <inertia ixx="0.111172755531" ixy="0.0" ixz="0.0" iyy="0.111172755531" iyz="0.0" izz="0.21942"/>
</inertial>
</link>
<joint name="r_wrist_3_joint" type="revolute">
<parent link="r_wrist_2_link"/>
<child link="r_wrist_3_link"/>
<origin rpy="0.0 0.0 0.0" xyz="0.0 0.0 0.09465"/>
<axis xyz="0 1 0"/>
<limit effort="28.0" lower="-3.14159265" upper="3.14159265" velocity="3.2"/>
<dynamics damping="0.0" friction="0.0"/>
</joint>
<link name="r_wrist_3_link">
<visual>
 <geometry>
   <mesh filename="package://ur5/meshes/visual/Wrist3.obj"/>
 </geometry>
 <material name="LightGrey">
   <color rgba="0.7 0.7 0.7 1.0"/>
 </material>
</visual>
<collision>
 <geometry>
   <mesh filename="package://ur5/meshes/collision/Wrist3.stl"/>
 </geometry>
    <origin rpy="1.570796325 0.0 0.0" xyz="0.0 0.0 0.0"/>
</collision>
<inertial>
 <mass value="0.1879"/>
 <origin rpy="0 0 0" xyz="0.0 0.0 0.0"/>
 <inertia ixx="0.0171364731454" ixy="0.0" ixz="0.0" iyy="0.0171364731454" iyz="0.0" izz="0.033822"/>
</inertial>
</link>
<joint name="r_fixed_joint" type="fixed">
<parent link="r_wrist_3_link"/>
<child link="r_fixed_link"/>
    <origin rpy="3.1415926585 3.1415926585 -1.570796325" xyz="0.0 0.0823 0.0"/>
</joint>
<link name="r_fixed_link">
<visual>
 <geometry>
   <mesh filename="package://ur5/meshes/visual/FixedR.obj"/>
 </geometry>
 <material name="LightGrey">
   <color rgba="0.7 0.7 0.7 1.0"/>
 </material>
</visual>
<collision>
    <origin rpy="1.570796325 0.0 0.0" xyz="0.0 0.0 0.0"/>
 <geometry>
   <mesh filename="package://ur5/meshes/collision/FixedR.stl"/>
 </geometry>
</collision>
<inertial>
 <mass value="0.1"/>
    <origin rpy="0 0 0" xyz="0.0 0.0 0.0"/>
 <inertia ixx="0.01" ixy="0.0" ixz="0.0" iyy="0.01" iyz="0.0" izz="0.01"/>
</inertial>
</link>

<joint name="r_fixed_connector_joint" type="fixed">
<parent link="r_fixed_link"/>
<child link="r_fixed_connector_link"/>
    <!--<origin rpy="0.0 0.0 0" xyz="0.178 -0.0405 0.0"/>-->
    -<origin rpy="0.0 0.0 0" xyz="0.173 0.04150 0.0"/>
<axis xyz="0 0 1"/>
</joint>

<link name="r_fixed_connector_link">
<visual>
 <geometry>
   <mesh filename="package://ur5/meshes/visual/FixedConnectorR.obj"/>
 </geometry>
 <material name="LightGrey">
   <color rgba="0.7 0.7 0.7 1.0"/>
 </material>
</visual>
<collision>
    <origin rpy="1.570796325 0.0 0.0" xyz="0.0 0.0 0.0"/>
 <geometry>
   <mesh filename="package://ur5/meshes/collision/FixedConnectorR.stl"/>
 </geometry>
</collision>
<inertial>
 <mass value="0.01"/>
 <origin rpy="0 0 0" xyz="0.0 0.0 0.0"/>
 <inertia ixx="0.001" ixy="0.0" ixz="0.0" iyy="0.001" iyz="0.0" izz="0.001"/>
</inertial>
</link>

<joint name="r_fixed_sensor_joint" type="fixed">
<parent link="r_fixed_connector_link"/>
<child link="r_fixed_sensor_link"/>
<origin rpy="0.0 0.0 0" xyz="0.005 -0.0010 0.0"/>
<axis xyz="0 0 1"/>
</joint>

<link name="r_fixed_sensor_link">
<visual>
 <geometry>
   <mesh filename="package://ur5/meshes/visual/FixedSensorR.obj"/>
 </geometry>
 <material name="LightGrey">
   <color rgba="0.7 0.7 0.7 1.0"/>
 </material>
</visual>
<collision>
    <origin rpy="1.570796325 0.0 0.0" xyz="0.0 0.0 0.0"/>
 <geometry>
   <mesh filename="package://ur5/meshes/collision/FixedSensorR.stl"/>
 </geometry>
</collision>
<inertial>
 <mass value="0.01"/>
 <origin rpy="0 0 0" xyz="0.0 0.0 0.0"/>
 <inertia ixx="0.001" ixy="0.0" ixz="0.0" iyy="0.001" iyz="0.0" izz="0.001"/>
</inertial>
</link>

<joint name="r_fixed_finger_joint" type="fixed">
<parent link="r_fixed_sensor_link"/>
<child link="r_fixed_finger_link"/>
<origin rpy="0.0 0.0 0" xyz="0.023 0.0 0.0"/>
<axis xyz="0 0 1"/>
<limit effort="28.0" lower="-3.14159265" upper="3.14159265" velocity="3.2"/>
</joint>

<link name="r_fixed_finger_link">
<visual>
 <geometry>
   <mesh filename="package://ur5/meshes/visual/FixedFingerR.obj"/>
 </geometry>
 <material name="LightGrey">
   <color rgba="0.7 0.7 0.7 1.0"/>
 </material>
</visual>
<collision>
    <origin rpy="1.570796325 0.0 0.0" xyz="0.0 0.0 0.0"/>
 <geometry>
   <mesh filename="package://ur5/meshes/collision/FixedFingerR.stl"/>
 </geometry>
</collision>
<inertial>
 <mass value="0.01"/>
 <origin rpy="0 0 0" xyz="0.0 0.0 0.0"/>
 <inertia ixx="0.001" ixy="0.0" ixz="0.0" iyy="0.001" iyz="0.0" izz="0.001"/>
</inertial>
</link>


<joint name="r_move_joint" type="revolute">
<parent link="r_fixed_link"/>
<child link="r_move_link"/>
<origin rpy="0.0 0.0 0" xyz="0.053 -0.0085 0.0"/>
<axis xyz="0 0 1"/>
<limit effort="28.0" lower="-3.14159265" upper="3.14159265" velocity="3.2"/>
</joint>



<link name="r_move_link">
<visual>
 <geometry>
   <mesh filename="package://ur5/meshes/visual/MoveR.obj"/>
 </geometry>
 <material name="LightGrey">
   <color rgba="0.7 0.7 0.7 1.0"/>
 </material>
</visual>
<collision>
    <origin rpy="1.570796325 0.0 0.0" xyz="0.0 0.0 0.0"/>
 <geometry>
   <mesh filename="package://ur5/meshes/collision/MoveR.stl"/>
 </geometry>
</collision>
<inertial>
 <mass value="0.01"/>
 <origin rpy="0 0 0" xyz="0.0 0.0 0.0"/>
 <inertia ixx="0.001" ixy="0.0" ixz="0.0" iyy="0.001" iyz="0.0" izz="0.001"/>
</inertial>
</link>

<joint name="r_move_connector_joint" type="fixed">
<parent link="r_move_link"/>
<child link="r_move_connector_link"/>
    -<origin rpy="0.0 0.0 0" xyz="0.1205 0.01975 0.0"/>
<axis xyz="0 0 1"/>
</joint>

<link name="r_move_connector_link">
<visual>
 <geometry>
   <mesh filename="package://ur5/meshes/visual/MoveConnectorR.obj"/>
 </geometry>
 <material name="LightGrey">
   <color rgba="0.7 0.7 0.7 1.0"/>
 </material>
</visual>
<collision>
    <origin rpy="1.570796325 0.0 0.0" xyz="0.0 0.0 0.0"/>
 <geometry>
   <mesh filename="package://ur5/meshes/collision/MoveConnectorR.stl"/>
 </geometry>
</collision>
<inertial>
 <mass value="0.01"/>
 <origin rpy="0 0 0" xyz="0.0 0.0 0.0"/>
 <inertia ixx="0.001" ixy="0.0" ixz="0.0" iyy="0.001" iyz="0.0" izz="0.001"/>
</inertial>
</link>

<joint name="r_move_sensor_joint" type="fixed">
<parent link="r_move_connector_link"/>
<child link="r_move_sensor_link"/>
    <origin rpy="0.0 0.0 0" xyz="0.0045 -0.00375 0.0"/>
<axis xyz="0 0 1"/>
</joint>

<link name="r_move_sensor_link">
<visual>
 <geometry>
   <mesh filename="package://ur5/meshes/visual/MoveSensorR.obj"/>
 </geometry>
</visual>
<collision>
    <origin rpy="1.570796325 0.0 0.0" xyz="0.0 0.0 0.0"/>
 <geometry>
   <mesh filename="package://ur5/meshes/collision/MoveSensorR.stl"/>
 </geometry>
</collision>
<inertial>
 <mass value="0.01"/>
 <origin rpy="0 0 0" xyz="0.0 0.0 0.0"/>
 <inertia ixx="0.001" ixy="0.0" ixz="0.0" iyy="0.001" iyz="0.0" izz="0.001"/>
</inertial>
</link>

<joint name="r_move_finger_joint" type="fixed">
<parent link="r_move_sensor_link"/>
<child link="r_move_finger_link"/>
<origin rpy="0.0 0.0 0" xyz="0.023 0.0 0.0"/>
<axis xyz="0 0 1"/>
</joint>

<link name="r_move_finger_link">
<visual>
 <geometry>
   <mesh filename="package://ur5/meshes/visual/MoveFingerR.obj"/>
 </geometry>
 <material name="LightGrey">
   <color rgba="0.7 0.7 0.7 1.0"/>
 </material>
</visual>
<collision>
    <origin rpy="1.570796325 0.0 0.0" xyz="0.0 0.0 0.0"/>
 <geometry>
   <mesh filename="package://ur5/meshes/collision/MoveFingerR.stl"/>
 </geometry>
</collision>
<inertial>
 <mass value="0.01"/>
 <origin rpy="0 0 0" xyz="0.0 0.0 0.0"/>
 <inertia ixx="0.001" ixy="0.0" ixz="0.0" iyy="0.001" iyz="0.0" izz="0.001"/>
</inertial>
</link>


     <transmission name="l_shoulder_pan_trans">
    <type>transmission_interface/SimpleTransmission</type>
    <joint name="l_shoulder_pan_joint">
      <hardwareInterface>PositionJointInterface</hardwareInterface>
    </joint>
    <actuator name="l_shoulder_pan_motor">
      <mechanicalReduction>1</mechanicalReduction>
    </actuator>
  </transmission>
  <transmission name="l_shoulder_lift_trans">
    <type>transmission_interface/SimpleTransmission</type>
    <joint name="l_shoulder_lift_joint">
      <hardwareInterface>PositionJointInterface</hardwareInterface>
    </joint>
    <actuator name="l_shoulder_lift_motor">
      <mechanicalReduction>1</mechanicalReduction>
    </actuator>
  </transmission>
  <transmission name="l_elbow_trans">
    <type>transmission_interface/SimpleTransmission</type>
    <joint name="l_elbow_joint">
      <hardwareInterface>PositionJointInterface</hardwareInterface>
    </joint>
    <actuator name="l_elbow_motor">
      <mechanicalReduction>1</mechanicalReduction>
    </actuator>
  </transmission>
  <transmission name="l_wrist_1_trans">
    <type>transmission_interface/SimpleTransmission</type>
    <joint name="l_wrist_1_joint">
      <hardwareInterface>PositionJointInterface</hardwareInterface>
    </joint>
    <actuator name="l_wrist_1_motor">
      <mechanicalReduction>1</mechanicalReduction>
    </actuator>
  </transmission>
  <transmission name="l_wrist_2_trans">
    <type>transmission_interface/SimpleTransmission</type>
    <joint name="l_wrist_2_joint">
      <hardwareInterface>PositionJointInterface</hardwareInterface>
    </joint>
    <actuator name="l_wrist_2_motor">
      <mechanicalReduction>1</mechanicalReduction>
    </actuator>
  </transmission>
  <transmission name="l_wrist_3_trans">
    <type>transmission_interface/SimpleTransmission</type>
    <joint name="l_wrist_3_joint">
      <hardwareInterface>PositionJointInterface</hardwareInterface>
    </joint>
    <actuator name="l_wrist_3_motor">
      <mechanicalReduction>1</mechanicalReduction>
    </actuator>
  </transmission>
  <transmission name="l_move_trans">
    <type>transmission_interface/SimpleTransmission</type>
    <joint name="l_move_joint">
      <hardwareInterface>PositionJointInterface</hardwareInterface>
    </joint>
    <actuator name="l_move_motor">
      <mechanicalReduction>1</mechanicalReduction>
    </actuator>
  </transmission>


  <transmission name="r_shoulder_pan_trans">
    <type>transmission_interface/SimpleTransmission</type>
    <joint name="r_shoulder_pan_joint">
      <hardwareInterface>PositionJointInterface</hardwareInterface>
    </joint>
    <actuator name="r_shoulder_pan_motor">
      <mechanicalReduction>1</mechanicalReduction>
    </actuator>
  </transmission>
  <transmission name="r_shoulder_lift_trans">
    <type>transmission_interface/SimpleTransmission</type>
    <joint name="r_shoulder_lift_joint">
      <hardwareInterface>PositionJointInterface</hardwareInterface>
    </joint>
    <actuator name="r_shoulder_lift_motor">
      <mechanicalReduction>1</mechanicalReduction>
    </actuator>
  </transmission>
  <transmission name="r_elbow_trans">
    <type>transmission_interface/SimpleTransmission</type>
    <joint name="r_elbow_joint">
      <hardwareInterface>PositionJointInterface</hardwareInterface>
    </joint>
    <actuator name="r_elbow_motor">
      <mechanicalReduction>1</mechanicalReduction>
    </actuator>
  </transmission>
  <transmission name="r_wrist_1_trans">
    <type>transmission_interface/SimpleTransmission</type>
    <joint name="r_wrist_1_joint">
      <hardwareInterface>PositionJointInterface</hardwareInterface>
    </joint>
    <actuator name="r_wrist_1_motor">
      <mechanicalReduction>1</mechanicalReduction>
    </actuator>
  </transmission>
  <transmission name="r_wrist_2_trans">
    <type>transmission_interface/SimpleTransmission</type>
    <joint name="r_wrist_2_joint">
      <hardwareInterface>PositionJointInterface</hardwareInterface>
    </joint>
    <actuator name="r_wrist_2_motor">
      <mechanicalReduction>1</mechanicalReduction>
    </actuator>
  </transmission>
  <transmission name="r_wrist_3_trans">
    <type>transmission_interface/SimpleTransmission</type>
    <joint name="r_wrist_3_joint">
      <hardwareInterface>PositionJointInterface</hardwareInterface>
    </joint>
    <actuator name="r_wrist_3_motor">
      <mechanicalReduction>1</mechanicalReduction>
    </actuator>
  </transmission>
  <transmission name="r_move_trans">
    <type>transmission_interface/SimpleTransmission</type>
    <joint name="r_move_joint">
      <hardwareInterface>PositionJointInterface</hardwareInterface>
    </joint>
    <actuator name="r_move_motor">
      <mechanicalReduction>1</mechanicalReduction>
    </actuator>
  </transmission>

</robot>
